2023-11-02 12:30:59,753 INFO    StreamThr :41658 [internal.py:wandb_internal():86] W&B internal server running at pid: 41658, started at: 2023-11-02 12:30:59.752389
2023-11-02 12:30:59,755 DEBUG   HandlerThread:41658 [handler.py:handle_request():146] handle_request: status
2023-11-02 12:30:59,759 INFO    WriterThread:41658 [datastore.py:open_for_write():85] open: /home/wangzihanggg/codespace/SwinDePose/swin_de_pose/wandb/run-20231102_123059-7r0ndfhd/run-7r0ndfhd.wandb
2023-11-02 12:30:59,760 DEBUG   SenderThread:41658 [sender.py:send():380] send: header
2023-11-02 12:30:59,781 DEBUG   SenderThread:41658 [sender.py:send():380] send: run
2023-11-02 12:31:00,864 ERROR   SenderThread:41658 [internal_api.py:execute():369] 404 response executing GraphQL.
2023-11-02 12:31:00,864 ERROR   SenderThread:41658 [internal_api.py:execute():370] {"errors":[{"message":"project not found","path":["upsertBucket"]}],"data":{"upsertBucket":null}}
2023-11-02 12:31:00,864 ERROR   SenderThread:41658 [sender.py:send_run():977] It appears that you do not have permission to access the requested resource. Please reach out to the project owner to grant you access. If you have the correct permissions, verify that there are no issues with your networking setup.(Error 404: Not Found)
Traceback (most recent call last):
  File "/home/wangzihanggg/miniconda3/envs/pytorch/lib/python3.8/site-packages/wandb/sdk/lib/retry.py", line 131, in __call__
    result = self._call_fn(*args, **kwargs)
  File "/home/wangzihanggg/miniconda3/envs/pytorch/lib/python3.8/site-packages/wandb/sdk/internal/internal_api.py", line 366, in execute
    return self.client.execute(*args, **kwargs)  # type: ignore
  File "/home/wangzihanggg/miniconda3/envs/pytorch/lib/python3.8/site-packages/wandb/vendor/gql-0.2.0/wandb_gql/client.py", line 52, in execute
    result = self._get_result(document, *args, **kwargs)
  File "/home/wangzihanggg/miniconda3/envs/pytorch/lib/python3.8/site-packages/wandb/vendor/gql-0.2.0/wandb_gql/client.py", line 60, in _get_result
    return self.transport.execute(document, *args, **kwargs)
  File "/home/wangzihanggg/miniconda3/envs/pytorch/lib/python3.8/site-packages/wandb/sdk/lib/gql_request.py", line 59, in execute
    request.raise_for_status()
  File "/home/wangzihanggg/miniconda3/envs/pytorch/lib/python3.8/site-packages/requests/models.py", line 1021, in raise_for_status
    raise HTTPError(http_error_msg, response=self)
requests.exceptions.HTTPError: 404 Client Error: Not Found for url: https://api.wandb.ai/graphql

During handling of the above exception, another exception occurred:

Traceback (most recent call last):
  File "/home/wangzihanggg/miniconda3/envs/pytorch/lib/python3.8/site-packages/wandb/sdk/internal/sender.py", line 975, in send_run
    self._init_run(run, config_value_dict)
  File "/home/wangzihanggg/miniconda3/envs/pytorch/lib/python3.8/site-packages/wandb/sdk/internal/sender.py", line 1013, in _init_run
    server_run, inserted, server_messages = self._api.upsert_run(
  File "/home/wangzihanggg/miniconda3/envs/pytorch/lib/python3.8/site-packages/wandb/apis/normalize.py", line 73, in wrapper
    raise err
  File "/home/wangzihanggg/miniconda3/envs/pytorch/lib/python3.8/site-packages/wandb/apis/normalize.py", line 41, in wrapper
    return func(*args, **kwargs)
  File "/home/wangzihanggg/miniconda3/envs/pytorch/lib/python3.8/site-packages/wandb/sdk/internal/internal_api.py", line 2007, in upsert_run
    response = self.gql(
  File "/home/wangzihanggg/miniconda3/envs/pytorch/lib/python3.8/site-packages/wandb/sdk/internal/internal_api.py", line 338, in gql
    ret = self._retry_gql(
  File "/home/wangzihanggg/miniconda3/envs/pytorch/lib/python3.8/site-packages/wandb/sdk/lib/retry.py", line 147, in __call__
    retry_timedelta_triggered = check_retry_fn(e)
  File "/home/wangzihanggg/miniconda3/envs/pytorch/lib/python3.8/site-packages/wandb/util.py", line 964, in check_retry_fn
    return fallback_retry_fn(e)
  File "/home/wangzihanggg/miniconda3/envs/pytorch/lib/python3.8/site-packages/wandb/util.py", line 906, in no_retry_auth
    raise CommError(
wandb.errors.CommError: It appears that you do not have permission to access the requested resource. Please reach out to the project owner to grant you access. If you have the correct permissions, verify that there are no issues with your networking setup.(Error 404: Not Found)
2023-11-02 12:31:01,791 DEBUG   HandlerThread:41658 [handler.py:handle_request():146] handle_request: shutdown
2023-11-02 12:31:01,792 INFO    HandlerThread:41658 [handler.py:finish():866] shutting down handler
2023-11-02 12:31:01,868 INFO    SenderThread:41658 [sender.py:finish():1534] shutting down sender
2023-11-02 12:31:02,782 INFO    WriterThread:41658 [datastore.py:close():294] close: /home/wangzihanggg/codespace/SwinDePose/swin_de_pose/wandb/run-20231102_123059-7r0ndfhd/run-7r0ndfhd.wandb
