2023-11-03 00:40:20,527 INFO    StreamThr :27349 [internal.py:wandb_internal():86] W&B internal server running at pid: 27349, started at: 2023-11-03 00:40:20.526448
2023-11-03 00:40:20,528 DEBUG   HandlerThread:27349 [handler.py:handle_request():146] handle_request: status
2023-11-03 00:40:20,531 INFO    WriterThread:27349 [datastore.py:open_for_write():85] open: /home/wangzihanggg/codespace/SwinDePose/swin_de_pose/wandb/run-20231103_004020-n8ck9yup/run-n8ck9yup.wandb
2023-11-03 00:40:20,531 DEBUG   SenderThread:27349 [sender.py:send():380] send: header
2023-11-03 00:40:20,550 DEBUG   SenderThread:27349 [sender.py:send():380] send: run
2023-11-03 00:40:21,936 ERROR   SenderThread:27349 [internal_api.py:execute():369] 403 response executing GraphQL.
2023-11-03 00:40:21,936 ERROR   SenderThread:27349 [internal_api.py:execute():370] {"errors":[{"message":"permission denied","path":["upsertBucket"],"extensions":{"code":"PERMISSION_ERROR"}}],"data":{"upsertBucket":null}}
2023-11-03 00:40:21,937 ERROR   SenderThread:27349 [sender.py:send_run():977] It appears that you do not have permission to access the requested resource. Please reach out to the project owner to grant you access. If you have the correct permissions, verify that there are no issues with your networking setup.(Error 403: Forbidden)
Traceback (most recent call last):
  File "/home/wangzihanggg/miniconda3/envs/pytorch/lib/python3.8/site-packages/wandb/sdk/lib/retry.py", line 131, in __call__
    result = self._call_fn(*args, **kwargs)
  File "/home/wangzihanggg/miniconda3/envs/pytorch/lib/python3.8/site-packages/wandb/sdk/internal/internal_api.py", line 366, in execute
    return self.client.execute(*args, **kwargs)  # type: ignore
  File "/home/wangzihanggg/miniconda3/envs/pytorch/lib/python3.8/site-packages/wandb/vendor/gql-0.2.0/wandb_gql/client.py", line 52, in execute
    result = self._get_result(document, *args, **kwargs)
  File "/home/wangzihanggg/miniconda3/envs/pytorch/lib/python3.8/site-packages/wandb/vendor/gql-0.2.0/wandb_gql/client.py", line 60, in _get_result
    return self.transport.execute(document, *args, **kwargs)
  File "/home/wangzihanggg/miniconda3/envs/pytorch/lib/python3.8/site-packages/wandb/sdk/lib/gql_request.py", line 59, in execute
    request.raise_for_status()
  File "/home/wangzihanggg/miniconda3/envs/pytorch/lib/python3.8/site-packages/requests/models.py", line 1021, in raise_for_status
    raise HTTPError(http_error_msg, response=self)
requests.exceptions.HTTPError: 403 Client Error: Forbidden for url: https://api.wandb.ai/graphql

During handling of the above exception, another exception occurred:

Traceback (most recent call last):
  File "/home/wangzihanggg/miniconda3/envs/pytorch/lib/python3.8/site-packages/wandb/sdk/internal/sender.py", line 975, in send_run
    self._init_run(run, config_value_dict)
  File "/home/wangzihanggg/miniconda3/envs/pytorch/lib/python3.8/site-packages/wandb/sdk/internal/sender.py", line 1013, in _init_run
    server_run, inserted, server_messages = self._api.upsert_run(
  File "/home/wangzihanggg/miniconda3/envs/pytorch/lib/python3.8/site-packages/wandb/apis/normalize.py", line 73, in wrapper
    raise err
  File "/home/wangzihanggg/miniconda3/envs/pytorch/lib/python3.8/site-packages/wandb/apis/normalize.py", line 41, in wrapper
    return func(*args, **kwargs)
  File "/home/wangzihanggg/miniconda3/envs/pytorch/lib/python3.8/site-packages/wandb/sdk/internal/internal_api.py", line 2007, in upsert_run
    response = self.gql(
  File "/home/wangzihanggg/miniconda3/envs/pytorch/lib/python3.8/site-packages/wandb/sdk/internal/internal_api.py", line 338, in gql
    ret = self._retry_gql(
  File "/home/wangzihanggg/miniconda3/envs/pytorch/lib/python3.8/site-packages/wandb/sdk/lib/retry.py", line 147, in __call__
    retry_timedelta_triggered = check_retry_fn(e)
  File "/home/wangzihanggg/miniconda3/envs/pytorch/lib/python3.8/site-packages/wandb/util.py", line 964, in check_retry_fn
    return fallback_retry_fn(e)
  File "/home/wangzihanggg/miniconda3/envs/pytorch/lib/python3.8/site-packages/wandb/util.py", line 906, in no_retry_auth
    raise CommError(
wandb.errors.CommError: It appears that you do not have permission to access the requested resource. Please reach out to the project owner to grant you access. If you have the correct permissions, verify that there are no issues with your networking setup.(Error 403: Forbidden)
2023-11-03 00:40:23,005 DEBUG   HandlerThread:27349 [handler.py:handle_request():146] handle_request: shutdown
2023-11-03 00:40:23,005 INFO    HandlerThread:27349 [handler.py:finish():866] shutting down handler
2023-11-03 00:40:23,551 INFO    WriterThread:27349 [datastore.py:close():294] close: /home/wangzihanggg/codespace/SwinDePose/swin_de_pose/wandb/run-20231103_004020-n8ck9yup/run-n8ck9yup.wandb
2023-11-03 00:40:23,992 INFO    SenderThread:27349 [sender.py:finish():1534] shutting down sender
